<?xml version="1.0" ?>
<!-- =================================================================================== -->
<!-- |    This document was autogenerated by xacro from /home/axel/ROS_ws/integration_ws/src/integration_ros_hc10_kinect/hc10_kinect_description/urdf/hc10.xacro | -->
<!-- |    EDITING THIS FILE BY HAND IS NOT RECOMMENDED                                 | -->
<!-- =================================================================================== -->
<robot name="motoman_hc10">
    <!-- link list -->
    <link name="world" />
    <link name="base_link">
        <visual>
            <geometry>
                <mesh filename="package://hc10_kinect_description/meshes/visual/base_link.dae" />
            </geometry>
            <material name="">
                <color rgba="0.12941176470588237 0.14901960784313725 0.7490196078431373 1.0" />
            </material>
        </visual>
        <collision>
            <geometry>
                <mesh filename="package://hc10_kinect_description/meshes/collision/base_link.stl" />
            </geometry>
        </collision>
        <inertial>
            <origin rpy="0 0 0" xyz="0 0 0" />
            <mass value="0.1" />
            <inertia ixx="0.03" ixy="0.03" ixz="0.03" iyy="0.0" iyz="0.0" izz="0.0" />
        </inertial>
    </link>
    <link name="link_1_s">
        <visual>
            <geometry>
                <mesh filename="package://hc10_kinect_description/meshes/visual/link_1_s.dae" />
            </geometry>
            <material name="">
                <color rgba="0.12941176470588237 0.14901960784313725 0.7490196078431373 1.0" />
            </material>
        </visual>
        <collision>
            <geometry>
                <mesh filename="package://hc10_kinect_description/meshes/collision/link_1_s.stl" />
            </geometry>
        </collision>
        <inertial>
            <origin rpy="0 0 0" xyz="0 0 0" />
            <mass value="0.1" />
            <inertia ixx="0.03" ixy="0.03" ixz="0.03" iyy="0.0" iyz="0.0" izz="0.0" />
        </inertial>
    </link>
    <link name="link_2_l">
        <visual>
            <geometry>
                <mesh filename="package://hc10_kinect_description/meshes/visual/link_2_l.dae" />
            </geometry>
            <material name="">
                <color rgba="0.12941176470588237 0.14901960784313725 0.7490196078431373 1.0" />
            </material>
        </visual>
        <collision>
            <geometry>
                <mesh filename="package://hc10_kinect_description/meshes/collision/link_2_l.stl" />
            </geometry>
        </collision>
        <inertial>
            <origin rpy="0 0 0" xyz="0 0 0" />
            <mass value="0.1" />
            <inertia ixx="0.03" ixy="0.03" ixz="0.03" iyy="0.0" iyz="0.0" izz="0.0" />
        </inertial>
    </link>
    <link name="link_3_u">
        <visual>
            <geometry>
                <mesh filename="package://hc10_kinect_description/meshes/visual/link_3_u.dae" />
            </geometry>
            <material name="">
                <color rgba="0.12941176470588237 0.14901960784313725 0.7490196078431373 1.0" />
            </material>
        </visual>
        <collision>
            <geometry>
                <mesh filename="package://hc10_kinect_description/meshes/collision/link_3_u.stl" />
            </geometry>
        </collision>
        <inertial>
            <origin rpy="0 0 0" xyz="0 0 0" />
            <mass value="0.1" />
            <inertia ixx="0.03" ixy="0.03" ixz="0.03" iyy="0.0" iyz="0.0" izz="0.0" />
        </inertial>
    </link>
    <link name="link_4_r">
        <visual>
            <geometry>
                <mesh filename="package://hc10_kinect_description/meshes/visual/link_4_r.dae" />
            </geometry>
            <material name="">
                <color rgba="0.12941176470588237 0.14901960784313725 0.7490196078431373 1.0" />
            </material>
        </visual>
        <collision>
            <geometry>
                <mesh filename="package://hc10_kinect_description/meshes/collision/link_4_r.stl" />
            </geometry>
        </collision>
        <inertial>
            <origin rpy="0 0 0" xyz="0 0 0" />
            <mass value="0.1" />
            <inertia ixx="0.03" ixy="0.03" ixz="0.03" iyy="0.0" iyz="0.0" izz="0.0" />
        </inertial>
    </link>
    <link name="link_5_b">
        <visual>
            <geometry>
                <mesh filename="package://hc10_kinect_description/meshes/visual/link_5_b.dae" />
            </geometry>
            <material name="">
                <color rgba="0.12941176470588237 0.14901960784313725 0.7490196078431373 1.0" />
            </material>
        </visual>
        <collision>
            <geometry>
                <mesh filename="package://hc10_kinect_description/meshes/collision/link_5_b.stl" />
            </geometry>
        </collision>
        <inertial>
            <origin rpy="0 0 0" xyz="0 0 0" />
            <mass value="0.1" />
            <inertia ixx="0.03" ixy="0.03" ixz="0.03" iyy="0.0" iyz="0.0" izz="0.0" />
        </inertial>
    </link>
    <link name="link_6_t">
        <visual>
            <geometry>
                <mesh filename="package://hc10_kinect_description/meshes/visual/link_6_t.dae" />
            </geometry>
            <material name="">
                <color rgba="0.12941176470588237 0.14901960784313725 0.7490196078431373 1.0" />
            </material>
        </visual>
        <collision>
            <geometry>
                <mesh filename="package://hc10_kinect_description/meshes/collision/link_6_t.stl" />
            </geometry>
        </collision>
        <inertial>
            <origin rpy="0 0 0" xyz="0 0 0" />
            <mass value="0.1" />
            <inertia ixx="0.03" ixy="0.03" ixz="0.03" iyy="0.0" iyz="0.0" izz="0.0" />
        </inertial>
    </link>
    <link name="tool0" />

<!-- ///////////////////////////////// -->
    <!-- <xacro:property name="PI" value="3.14159265359" /> -->

    <link name="kinect_link">
        <visual>
            <geometry>
                <box size="0.2 0.05 0.05"/>
            </geometry>
            <material name="blue"/>
        </visual>
        <collision>
            <geometry>
                <box size="0.2 0.05 0.05"/>
            </geometry>
        </collision>
    </link>


    <!-- Définition du joint qui attache la Kinect au robot -->
    <joint name="kinect_joint" type="fixed">
        <parent link="tool0"/>
        <child link="kinect_link"/>
        <origin xyz="0 0 0.03" rpy="0 0 0"/>
    </joint>

    <gazebo reference="kinect_link">
    <sensor name="kinect_camera" type="depth">
        <update_rate>20</update_rate>
        <camera>
            <horizontal_fov>1.047198</horizontal_fov>
            <image>
                <width>640</width>
                <height>480</height>
                <format>B8G8R8</format>
            </image>
            <clip>
                <near>0.05</near>
                <far>3</far>
            </clip>
        </camera>
        <plugin name="kinect_controller" filename="libgazebo_ros_openni_kinect.so">
        <baseline>0.1</baseline>
        <alwaysOn>true</alwaysOn>
        <updateRate>10</updateRate>
        <cameraName>camera_ir</cameraName>
        <imageTopicName>/camera/color/image_raw</imageTopicName>
        <cameraInfoTopicName>/camera/color/camera_info</cameraInfoTopicName>
        <depthImageTopicName>/camera/depth/image_raw</depthImageTopicName>
        <depthImageCameraInfoTopicName>/camera/depth/camera_info</depthImageCameraInfoTopicName>
        <pointCloudTopicName>/camera/depth/points</pointCloudTopicName>
        <frameName>kinect_link</frameName>
        <distortion_k1>0.0</distortion_k1>
        <distortion_k2>0.0</distortion_k2>
        <distortion_k3>0.0</distortion_k3>
        <distortion_t1>0.0</distortion_t1>
        <distortion_t2>0.0</distortion_t2>
        <pointCloudCutoff>0.16</pointCloudCutoff>
        <pointCloudCutoffMax>10.0</pointCloudCutoffMax>
        </plugin>
    </sensor>
</gazebo>



    <!-- end of link list -->
    <!-- joint list -->
    <joint name="world_fixed" type="fixed">
        <parent link="world" />
        <child link="base_link" />
    </joint>
    <joint name="joint_1_s" type="revolute">
        <parent link="base_link" />
        <child link="link_1_s" />
        <origin rpy="0 0 0" xyz="0 0 0.275" />
        <axis xyz="0 0 1" />
        <limit effort="368.48" lower="-3.141592653589793" upper="3.141592653589793" velocity="2.2689280275926285" />
        <dynamics damping="1" />
    </joint>
    <joint name="joint_2_l" type="revolute">
        <parent link="link_1_s" />
        <child link="link_2_l" />
        <origin rpy="0 0 0" xyz="0 0 0" />
        <axis xyz="0 1 0" />
        <limit effort="368.48" lower="-3.141592653589793" upper="3.141592653589793" velocity="2.2689280275926285" />
        <dynamics damping="1" />
    </joint>
    <joint name="joint_3_u" type="revolute">
        <parent link="link_2_l" />
        <child link="link_3_u" />
        <origin rpy="0 0 0" xyz="0 0 0.700" />
        <axis xyz="0 -1 0" />
        <limit effort="141.12" lower="-0.08726646259971647" upper="6.19591884457987" velocity="3.141592653589793" />
        <dynamics damping="1" />
    </joint>
    <joint name="joint_4_r" type="revolute">
        <parent link="link_3_u" />
        <child link="link_4_r" />
        <origin rpy="0 0 0" xyz="0 0 -0.500" />
        <axis xyz="0 0 1" />
        <limit effort="39.20" lower="-3.141592653589793" upper="3.141592653589793" velocity="3.141592653589793" />
        <dynamics damping="1" />
    </joint>
    <joint name="joint_5_b" type="revolute">
        <parent link="link_4_r" />
        <child link="link_5_b" />
        <origin rpy="0 0 0" xyz="0 0.162 0" />
        <axis xyz="0 -1 0" />
        <limit effort="31.36" lower="-3.141592653589793" upper="3.141592653589793" velocity="4.363323129985824" />
        <dynamics damping="1" />
    </joint>
    <joint name="joint_6_t" type="revolute">
        <parent link="link_5_b" />
        <child link="link_6_t" />
        <origin rpy="0 0 0" xyz="0 0 0" />
        <axis xyz="0 0 1" />
        <limit effort="31.36" lower="-3.141592653589793" upper="3.141592653589793" velocity="4.363323129985824" />
        <dynamics damping="1" />
    </joint>
    <joint name="joint_6_t-tool0" type="fixed">
        <origin rpy="3.141592653589793 0 0" xyz="0 0 -0.130" />
        <parent link="link_6_t" />
        <child link="tool0" />
    </joint>
    <!-- end of joint list -->
    <!-- ROS base_link to Robot Manufacturer World Coordinates transform -->
    <link name="base" />
    <joint name="base_link-base" type="fixed">
        <origin rpy="0 0 0" xyz="0 0 0.275" />
        <parent link="base_link" />
        <child link="base" />
    </joint>
    <transmission name="trans_joint_1_s">
        <type>transmission_interface/SimpleTransmission</type>
        <joint name="joint_1_s">
            <hardwareInterface>hardware_interface/VelocityJointInterface</hardwareInterface>
        </joint>
        <actuator name="joint_1_s_motor">
            <hardwareInterface>hardware_interface/VelocityJointInterface</hardwareInterface>
            <mechanicalReduction>1</mechanicalReduction>
        </actuator>
    </transmission>
    <transmission name="trans_joint_2_l">
        <type>transmission_interface/SimpleTransmission</type>
        <joint name="joint_2_l">
            <hardwareInterface>hardware_interface/VelocityJointInterface</hardwareInterface>
        </joint>
        <actuator name="joint_2_l_motor">
            <hardwareInterface>hardware_interface/VelocityJointInterface</hardwareInterface>
            <mechanicalReduction>1</mechanicalReduction>
        </actuator>
    </transmission>
    <transmission name="trans_joint_3_u">
        <type>transmission_interface/SimpleTransmission</type>
        <joint name="joint_3_u">
            <hardwareInterface>hardware_interface/VelocityJointInterface</hardwareInterface>
        </joint>
        <actuator name="joint_3_u_motor">
            <hardwareInterface>hardware_interface/VelocityJointInterface</hardwareInterface>
            <mechanicalReduction>1</mechanicalReduction>
        </actuator>
    </transmission>
    <transmission name="trans_joint_4_r">
        <type>transmission_interface/SimpleTransmission</type>
        <joint name="joint_4_r">
            <hardwareInterface>hardware_interface/VelocityJointInterface</hardwareInterface>
        </joint>
        <actuator name="joint_4_r_motor">
            <hardwareInterface>hardware_interface/VelocityJointInterface</hardwareInterface>
            <mechanicalReduction>1</mechanicalReduction>
        </actuator>
    </transmission>
    <transmission name="trans_joint_5_b">
        <type>transmission_interface/SimpleTransmission</type>
        <joint name="joint_5_b">
            <hardwareInterface>hardware_interface/VelocityJointInterface</hardwareInterface>
        </joint>
        <actuator name="joint_5_b_motor">
            <hardwareInterface>hardware_interface/VelocityJointInterface</hardwareInterface>
            <mechanicalReduction>1</mechanicalReduction>
        </actuator>
    </transmission>
    <transmission name="trans_joint_6_t">
        <type>transmission_interface/SimpleTransmission</type>
        <joint name="joint_6_t">
            <hardwareInterface>hardware_interface/VelocityJointInterface</hardwareInterface>
        </joint>
        <actuator name="joint_6_t_motor">
            <hardwareInterface>hardware_interface/VelocityJointInterface</hardwareInterface>
            <mechanicalReduction>1</mechanicalReduction>
        </actuator>
    </transmission>
    <gazebo>
        <plugin name="gazebo_ros_control" filename="libgazebo_ros_control.so">
            <robotNamespace>/</robotNamespace>
        </plugin>
    </gazebo>
</robot>

